Workbook
Name cell: [1]Sheet2!$B$2:$B$3
Name ComputationalMethods: '[2]Computational methods'!$B$3:$B$20
Name data_origin: '[2]data origin'!$B$2:$B$6
Name DisclosureCategory: [2]mandatory_item!$C$54:$C$57
Name measurement_processing_category: '[2]Characterization&Process'!$B$27:$AD$27
Name ProcessingEnvironment: '[2]Synthesis and processing'!$F$112:$F$120
Name PropertiesAddressed: '[2]Properties addressed'!$I$1:$X$1
Name RDE利用の目的: #REF!
Name SynthesisProcessing: '[2]Synthesis and processing'!$I$1:$T$1
Name 技術分類: '[3]Characterization methods'!$J$24:$Z$24
Name 計算手法: '[2]Computational methods'!$E$3:$E$20
Name 計測技術分類: '[3]Characterization methods'!$J$24:$Z$24
Name 構造的特徴: '[3]Structural features'!$I$25:$Q$25
Name 合成・プロセス: '[2]Synthesis and processing'!$I$22:$T$22
Name 処理環境: '[2]Synthesis and processing'!$G$112:$G$120
Name 測定環境: '[3]Characterization methods'!$G$118:$G$126
Name 特徴的性質: '[2]Properties addressed'!$I$28:$X$28
Name 物質タイプ: '[3]Material types'!$J$17:$T$17

Sheet 説明
A1: データセットテンプレート名 | B1: RDEDatasetTemplateSheet_RDE_VSM_mpms | C1: 各定義ファイルのdescriptionに利用されます
A2: データセットテンプレート名(英) | B2: RDEDatasetTemplateSheet_RDE_VSM_mpms | C2: 各定義ファイルのdescriptionに利用されます
A3: データセットテンプレートID | B3: RDEDatasetTemplateSheet_RDE_VSM_mpms | C3: $idで利用されます
A4: 概要 | B4: 標準データセットテンプレートRDE_VSM_mpms用RDEデータセットテンプレート
A6: 作成日 | B6: 46027
A7: 作成者 | B7: NIMS MDPF
A8: 最終更新日 | B8: 46027
A9: 最終更新者 | B9: NIMS MDPF
A11: 顧客指名
A12: 担当
A15: ver.2025.12.22
A18: 【説明】
A20: このExcelファイルは、excel2template.exeの入力ファイルです。
A21: 次の4つのシートで構成されています。
A23: ・説明
A24: ・要件定義(metadata-def.json)
A25: ・要件定義(catalog.schema.json)
A26: ・要件定義(invoice.schema.json)
A28: セルの色には以下の意味があります。
B30: 必須記入欄
B31: オプション記入欄(場合によって記入)
B32: 自動記入欄(ユーザは入力不要)
B33: 記入不要欄(入力不要)
A36: 列の削除は禁止です。
A37: また、必須項目が入力されていない場合はエラーになるので必ず記入をお願いします。

Sheet 要件定義(metadata-def.json)
A1: category | B1: output | C1: parameter_name | D1: order | E1: original_name | F1: original_type | G1: name/ja | H1: name/en | I1: taxonomy | J1: typeformat | K1: type | L1: format | M1: unit | N1: description | O1: uri | P1: mode | Q1: variable | R1: default | S1: sample
A2: カテゴリー (自由記述） | B2: 出力制御 (必ず選択) | C2: パラメータ名 (必ず記述) | D2: 表示順 | E2: 元項目名 | F2: 元データ型 | G2: 項目名(日本語) (必ず記述) | H2: 項目名(英語) (必ず記述) | I2: タクソノミー (番号記述） | J2: データ形式 (必ず選択) | K2: データ型 (自動入力） | L2: フォーマット (自動入力） | M2: 単位 (自由記述） | N2: 説明 (自由記述） | O2: URI (自由記述） | P2: 測定モード (自由記述） | Q2: 繰り返し (選択リスト） | R2: 固定値 (選択リスト） | S2: サンプル
A3: metadata | B3: ON | C3: appname | E3: APPNAME | G3: APPNAME | H3: APPNAME | J3: string | K3: =_xlfn.IFS(J3="integer","integer",J3="number","number",J3="array","array",J3="boolean","boolean",TRUE,"string") -> string | L3: =_xlfn.IFS(J3="datetime","date-time",J3="duration","duration",TRUE,"")
B4: ON | C4: byapp | E4: BYAPP | G4: BYAPP | H4: BYAPP | J4: string | K4: =_xlfn.IFS(J4="integer","integer",J4="number","number",J4="array","array",J4="boolean","boolean",TRUE,"string") -> string | L4: =_xlfn.IFS(J4="datetime","date-time",J4="duration","duration",TRUE,"")
B5: ON | C5: coil_serial_number | E5: COIL_SERIAL_NUMBER | G5: コイルシリアル番号 | H5: COIL_SERIAL_NUMBER | J5: string | K5: =_xlfn.IFS(J5="integer","integer",J5="number","number",J5="array","array",J5="boolean","boolean",TRUE,"string") -> string | L5: =_xlfn.IFS(J5="datetime","date-time",J5="duration","duration",TRUE,"")
B6: ON | C6: comment | E6: COMMENT | G6: コメント | H6: COMMENT | J6: string | K6: =_xlfn.IFS(J6="integer","integer",J6="number","number",J6="array","array",J6="boolean","boolean",TRUE,"string") -> string | L6: =_xlfn.IFS(J6="datetime","date-time",J6="duration","duration",TRUE,"")
B7: ON | C7: fieldgroup_dc | E7: FIELDGROUP_DC | G7: 磁場グループ_DC | H7: FIELDGROUP_DC | J7: string | K7: =_xlfn.IFS(J7="integer","integer",J7="number","number",J7="array","array",J7="boolean","boolean",TRUE,"string") -> string | L7: =_xlfn.IFS(J7="datetime","date-time",J7="duration","duration",TRUE,"")
B8: ON | C8: fieldgroup_vsm | E8: FIELDGROUP_VSM | G8: 磁場グループ_VSM | H8: FIELDGROUP_VSM | J8: string | K8: =_xlfn.IFS(J8="integer","integer",J8="number","number",J8="array","array",J8="boolean","boolean",TRUE,"string") -> string | L8: =_xlfn.IFS(J8="datetime","date-time",J8="duration","duration",TRUE,"")
B9: ON | C9: fileopentime | E9: FILEOPENTIME | G9: ファイルを開いた時間 | H9: FILEOPENTIME | J9: string | K9: =_xlfn.IFS(J9="integer","integer",J9="number","number",J9="array","array",J9="boolean","boolean",TRUE,"string") -> string | L9: =_xlfn.IFS(J9="datetime","date-time",J9="duration","duration",TRUE,"")
B10: ON | C10: moment_units | E10: MOMENT_UNITS | G10: 磁化の単位 | H10: MOMENT_UNITS | J10: string | K10: =_xlfn.IFS(J10="integer","integer",J10="number","number",J10="array","array",J10="boolean","boolean",TRUE,"string") -> string | L10: =_xlfn.IFS(J10="datetime","date-time",J10="duration","duration",TRUE,"")
B11: ON | C11: motor_hw_version | E11: MOTOR_HW_VERSION | G11: モーターハードウエアのバージョン | H11: MOTOR_HW_VERSION | J11: string | K11: =_xlfn.IFS(J11="integer","integer",J11="number","number",J11="array","array",J11="boolean","boolean",TRUE,"string") -> string | L11: =_xlfn.IFS(J11="datetime","date-time",J11="duration","duration",TRUE,"")
B12: ON | C12: motor_module_name | E12: MOTOR_MODULE_NAME | G12: モーターモジュールの名前 | H12: MOTOR_MODULE_NAME | J12: string | K12: =_xlfn.IFS(J12="integer","integer",J12="number","number",J12="array","array",J12="boolean","boolean",TRUE,"string") -> string | L12: =_xlfn.IFS(J12="datetime","date-time",J12="duration","duration",TRUE,"")
B13: ON | C13: motor_serial_number | E13: MOTOR_SERIAL_NUMBER | G13: モーターのシリアル番号 | H13: MOTOR_SERIAL_NUMBER | J13: string | K13: =_xlfn.IFS(J13="integer","integer",J13="number","number",J13="array","array",J13="boolean","boolean",TRUE,"string") -> string | L13: =_xlfn.IFS(J13="datetime","date-time",J13="duration","duration",TRUE,"")
B14: ON | C14: motor_software_version | E14: MOTOR_SOFTWARE_VERSION | G14: モーターソフトウエアのバージョン | H14: MOTOR_SOFTWARE_VERSION | J14: string | K14: =_xlfn.IFS(J14="integer","integer",J14="number","number",J14="array","array",J14="boolean","boolean",TRUE,"string") -> string | L14: =_xlfn.IFS(J14="datetime","date-time",J14="duration","duration",TRUE,"")
B15: ON | C15: oven_hw_version | E15: OVEN_HW_VERSION | G15: オーブンハードウエアのバージョン | H15: OVEN_HW_VERSION | J15: string | K15: =_xlfn.IFS(J15="integer","integer",J15="number","number",J15="array","array",J15="boolean","boolean",TRUE,"string") -> string | L15: =_xlfn.IFS(J15="datetime","date-time",J15="duration","duration",TRUE,"")
... B24: ON | C24: sample_molecular_weight | E24: SAMPLE_MOLECULAR_WEIGHT | G24: サンプルのモル量 | H24: SAMPLE_MOLECULAR_WEIGHT | J24: number | K24: =_xlfn.IFS(J24="integer","integer",J24="number","number",J24="array","array",J24="boolean","boolean",TRUE,"string") -> number | L24: =_xlfn.IFS(J24="datetime","date-time",J24="duration","duration",TRUE,"")
B25: ON | C25: sample_offset | E25: SAMPLE_OFFSET | G25: サンプルオフセット | H25: SAMPLE_OFFSET | J25: number | K25: =_xlfn.IFS(J25="integer","integer",J25="number","number",J25="array","array",J25="boolean","boolean",TRUE,"string") -> number | L25: =_xlfn.IFS(J25="datetime","date-time",J25="duration","duration",TRUE,"") | M25: mm
B26: ON | C26: sample_shape | E26: SAMPLE_SHAPE | G26: サンプル形状 | H26: SAMPLE_SHAPE | J26: string | K26: =_xlfn.IFS(J26="integer","integer",J26="number","number",J26="array","array",J26="boolean","boolean",TRUE,"string") -> string | L26: =_xlfn.IFS(J26="datetime","date-time",J26="duration","duration",TRUE,"")
B27: ON | C27: sample_size | E27: SAMPLE_SIZE | G27: サンプルサイズ | H27: SAMPLE_SIZE | J27: string | K27: =_xlfn.IFS(J27="integer","integer",J27="number","number",J27="array","array",J27="boolean","boolean",TRUE,"string") -> string | L27: =_xlfn.IFS(J27="datetime","date-time",J27="duration","duration",TRUE,"")
B28: ON | C28: sample_volume | E28: SAMPLE_VOLUME | G28: サンプル体積 | H28: SAMPLE_VOLUME | J28: number | K28: =_xlfn.IFS(J28="integer","integer",J28="number","number",J28="array","array",J28="boolean","boolean",TRUE,"string") -> number | L28: =_xlfn.IFS(J28="datetime","date-time",J28="duration","duration",TRUE,"")
B29: ON | C29: squid_hw_version | E29: SQUID_HW_VERSION | G29: SQUIDハードウエアのバージョン | H29: SQUID_HW_VERSION | J29: string | K29: =_xlfn.IFS(J29="integer","integer",J29="number","number",J29="array","array",J29="boolean","boolean",TRUE,"string") -> string | L29: =_xlfn.IFS(J29="datetime","date-time",J29="duration","duration",TRUE,"")
B30: ON | C30: squid_module_name | E30: SQUID_MODULE_NAME | G30: SQUIDモジュール名 | H30: SQUID_MODULE_NAME | J30: string | K30: =_xlfn.IFS(J30="integer","integer",J30="number","number",J30="array","array",J30="boolean","boolean",TRUE,"string") -> string | L30: =_xlfn.IFS(J30="datetime","date-time",J30="duration","duration",TRUE,"")
B31: ON | C31: squid_serial_number | E31: SQUID_SERIAL_NUMBER | G31: SQUIDシリアル番号 | H31: SQUID_SERIAL_NUMBER | J31: string | K31: =_xlfn.IFS(J31="integer","integer",J31="number","number",J31="array","array",J31="boolean","boolean",TRUE,"string") -> string | L31: =_xlfn.IFS(J31="datetime","date-time",J31="duration","duration",TRUE,"")
B32: ON | C32: squid_software_version | E32: SQUID_SOFTWARE_VERSION | G32: SQUIDソフトウエアのバージョン | H32: SQUID_SOFTWARE_VERSION | J32: string | K32: =_xlfn.IFS(J32="integer","integer",J32="number","number",J32="array","array",J32="boolean","boolean",TRUE,"string") -> string | L32: =_xlfn.IFS(J32="datetime","date-time",J32="duration","duration",TRUE,"")
B33: ON | C33: startupaxis_x | E33: STARTUPAXIS_X | G33: 測定開始時のX軸 | H33: STARTUPAXIS_X | J33: string | K33: =_xlfn.IFS(J33="integer","integer",J33="number","number",J33="array","array",J33="boolean","boolean",TRUE,"string") -> string | L33: =_xlfn.IFS(J33="datetime","date-time",J33="duration","duration",TRUE,"")
B34: ON | C34: startupaxis_y1 | E34: STARTUPAXIS_Y1 | G34: 測定開始時のY軸 | H34: STARTUPAXIS_Y1 | J34: string | K34: =_xlfn.IFS(J34="integer","integer",J34="number","number",J34="array","array",J34="boolean","boolean",TRUE,"string") -> string | L34: =_xlfn.IFS(J34="datetime","date-time",J34="duration","duration",TRUE,"")
B35: ON | C35: time | E35: TIME | G35: 時間 | H35: TIME | J35: string | K35: =_xlfn.IFS(J35="integer","integer",J35="number","number",J35="array","array",J35="boolean","boolean",TRUE,"string") -> string | L35: =_xlfn.IFS(J35="datetime","date-time",J35="duration","duration",TRUE,"")
B36: ON | C36: sample_size_height | G36: サンプルサイズ(縦) | H36: SAMPLE_SIZE(height) | J36: number | K36: =_xlfn.IFS(J36="integer","integer",J36="number","number",J36="array","array",J36="boolean","boolean",TRUE,"string") -> number | L36: =_xlfn.IFS(J36="datetime","date-time",J36="duration","duration",TRUE,"") | M36: mm
B37: ON | C37: sample_size_width | G37: サンプルサイズ(横) | H37: SAMPLE_SIZE(width) | J37: number | K37: =_xlfn.IFS(J37="integer","integer",J37="number","number",J37="array","array",J37="boolean","boolean",TRUE,"string") -> number | L37: =_xlfn.IFS(J37="datetime","date-time",J37="duration","duration",TRUE,"") | M37: mm
B38: ON | C38: sample_size_thickness | G38: サンプルサイズ(厚さ) | H38: SAMPLE_SIZE(thickness) | J38: number | K38: =_xlfn.IFS(J38="integer","integer",J38="number","number",J38="array","array",J38="boolean","boolean",TRUE,"string") -> number | L38: =_xlfn.IFS(J38="datetime","date-time",J38="duration","duration",TRUE,"") | M38: nm
B39: ON | C39: hc | G39: 保磁力 | H39: Hc | J39: string | K39: =_xlfn.IFS(J39="integer","integer",J39="number","number",J39="array","array",J39="boolean","boolean",TRUE,"string") -> string | L39: =_xlfn.IFS(J39="datetime","date-time",J39="duration","duration",TRUE,"") | M39: T
B40: ON | C40: br | G40: 残留磁化 | H40: Br | J40: string | K40: =_xlfn.IFS(J40="integer","integer",J40="number","number",J40="array","array",J40="boolean","boolean",TRUE,"string") -> string | L40: =_xlfn.IFS(J40="datetime","date-time",J40="duration","duration",TRUE,"") | M40: emu
B41: ON | C41: bs | G41: 磁束密度 | H41: Bs | J41: string | K41: =_xlfn.IFS(J41="integer","integer",J41="number","number",J41="array","array",J41="boolean","boolean",TRUE,"string") -> string | L41: =_xlfn.IFS(J41="datetime","date-time",J41="duration","duration",TRUE,"") | M41: emu
B42: ON | C42: brt | G42: 残留磁化x膜厚 | H42: Brt | J42: string | K42: =_xlfn.IFS(J42="integer","integer",J42="number","number",J42="array","array",J42="boolean","boolean",TRUE,"string") -> string | L42: =_xlfn.IFS(J42="datetime","date-time",J42="duration","duration",TRUE,"") | M42: memu/mm^2
B43: ON | C43: bs_per_volume | G43: 磁束密度/体積 | H43: Bs/Volume | J43: string | K43: =_xlfn.IFS(J43="integer","integer",J43="number","number",J43="array","array",J43="boolean","boolean",TRUE,"string") -> string | L43: =_xlfn.IFS(J43="datetime","date-time",J43="duration","duration",TRUE,"") | M43: emu/cm^3
B44: OFF | J44: string | K44: =_xlfn.IFS(J44="integer","integer",J44="number","number",J44="array","array",J44="boolean","boolean",TRUE,"string") -> string | L44: =_xlfn.IFS(J44="datetime","date-time",J44="duration","duration",TRUE,"")
B45: OFF | J45: string | K45: =_xlfn.IFS(J45="integer","integer",J45="number","number",J45="array","array",J45="boolean","boolean",TRUE,"string") -> string | L45: =_xlfn.IFS(J45="datetime","date-time",J45="duration","duration",TRUE,"")
B46: OFF | J46: string | K46: =_xlfn.IFS(J46="integer","integer",J46="number","number",J46="array","array",J46="boolean","boolean",TRUE,"string") -> string | L46: =_xlfn.IFS(J46="datetime","date-time",J46="duration","duration",TRUE,"")

Sheet 要件定義(invoice.schema.json)
A1: $schema | B1: https://json-schema.org/draft/2020-12/schema
A2: $id | B2: ="https://rde.nims.go.jp/rde/dataset-templates/"&説明!B3&"/invoice.schema.json" -> https://rde.nims.go.jp/rde/dataset-templates/RDEDatasetTemplateSheet_RDE_VSM_mpms/invoice.schema.json
A3: description | B3: =説明!B4&": 送状定義" -> 標準データセットテンプレートRDE_VSM_mpms用RDEデータセットテンプレート: 送状定義
A5: header | B5: category_name | C5: output | D5: parameter_name | E5: term | F5: label/ja | G5: label/en | H5: description | I5: examples | J5: options/unit | K5: taxonomy | L5: required | M5: typeformat | N5: type | O5: format | P5: options/widget | Q5: options/rows | R5: enum | S5: default | T5: const | U5: options/placeholder/ja | V5: options/placeholder/en | W5: maximum | X5: exclusiveMaximum | Y5: minimum | Z5: exclusiveMinimum | AA5: maxLength | AB5: minLength | AC5: pattern
A6: ヘッダー | B6: カテゴリー名 | C6: 出力制御 (必ず選択) | D6: パラメータ名 (必ず記述) | E6: 用語名 (必ず選択) | F6: 項目名(日本語) (必ず記述) | G6: 項目名(英語) (必ず記述) | H6: 説明 (自由記述） | I6: 内容サンプル (自由記述） | J6: 単位 (自由記述） | K6: タクソノミー (番号記述） | L6: 必須項目 (選択リスト） | M6: データ形式 (必ず選択) | N6: データ型 (自動入力） | O6: フォーマット (自動入力） | P6: テキストエリア (自動入力） | Q6: 行数 (数値記述） | R6: 値のリスト (カンマ区切り） | S6: 初期値 (自由記述） | T6: 固定値 (自由記述） | U6: プレイスホルダ(日本語) (自由記述） | V6: プレイスホルダ(英語) (自由記述） | W6: 数値上限(以下) (数値記述） | X6: 数値上限(未満) (数値記述） | Y6: 数値下限(以上) (数値記述） | Z6: 数値下限(より上) (数値記述） | AA6: 最大文字数 (数値記述） | AB6: 最小文字数 (数値記述） | AC6: 正規表現 (自由記述）
A7: custom | B7: 固有情報 | C7: ON | D7: background_removal | F7: バックグラウンド処理の有無 | G7: background_removal | M7: boolean | N7: =_xlfn.IFS(M7="integer","integer",M7="number","number",M7="boolean","boolean",TRUE,"string") -> boolean | O7: =_xlfn.IFS(M7="date","date",M7="markdown","markdown",M7="time", "time",M7="uri","uri",M7="uuid","uuid",TRUE,"") | S7: TRUE
C8: ON | D8: spike_removal | F8: スパイクノイズ除去処理の有無 | G8: spike_removal | M8: boolean | N8: =_xlfn.IFS(M8="integer","integer",M8="number","number",M8="boolean","boolean",TRUE,"string") -> boolean | O8: =_xlfn.IFS(M8="date","date",M8="markdown","markdown",M8="time", "time",M8="uri","uri",M8="uuid","uuid",TRUE,"") | S8: TRUE
C9: ON | D9: feature_acquisition | F9: 特徴量取得の有無 | G9: feature_acquisition | M9: boolean | N9: =_xlfn.IFS(M9="integer","integer",M9="number","number",M9="boolean","boolean",TRUE,"string") -> boolean | O9: =_xlfn.IFS(M9="date","date",M9="markdown","markdown",M9="time", "time",M9="uri","uri",M9="uuid","uuid",TRUE,"") | S9: TRUE
C10: ON | D10: sputtering_apparatus | F10: スパッタリング装置 | G10: Sputtering Apparatus | M10: string | N10: =_xlfn.IFS(M10="integer","integer",M10="number","number",M10="boolean","boolean",TRUE,"string") -> string | O10: =_xlfn.IFS(M10="date","date",M10="markdown","markdown",M10="time", "time",M10="uri","uri",M10="uuid","uuid",TRUE,"")
C11: ON | D11: specimen_label | F11: 試料名 | G11: Specimen label | M11: string | N11: =_xlfn.IFS(M11="integer","integer",M11="number","number",M11="boolean","boolean",TRUE,"string") -> string | O11: =_xlfn.IFS(M11="date","date",M11="markdown","markdown",M11="time", "time",M11="uri","uri",M11="uuid","uuid",TRUE,"")
C12: ON | D12: sample_year | F12: 試料作製年 | G12: Sample year | M12: string | N12: =_xlfn.IFS(M12="integer","integer",M12="number","number",M12="boolean","boolean",TRUE,"string") -> string | O12: =_xlfn.IFS(M12="date","date",M12="markdown","markdown",M12="time", "time",M12="uri","uri",M12="uuid","uuid",TRUE,"")
C13: ON | D13: sample_month | F13: 試料作製月 | G13: Sample month | M13: string | N13: =_xlfn.IFS(M13="integer","integer",M13="number","number",M13="boolean","boolean",TRUE,"string") -> string | O13: =_xlfn.IFS(M13="date","date",M13="markdown","markdown",M13="time", "time",M13="uri","uri",M13="uuid","uuid",TRUE,"")
C14: ON | D14: common_data_type | F14: 登録データタイプ | G14: Data Type | M14: string | N14: =_xlfn.IFS(M14="integer","integer",M14="number","number",M14="boolean","boolean",TRUE,"string") -> string | O14: =_xlfn.IFS(M14="date","date",M14="markdown","markdown",M14="time", "time",M14="uri","uri",M14="uuid","uuid",TRUE,"") | S14: VSM
C15: ON | D15: common_data_origin | F15: データの起源 | G15: Data Origin | M15: string | N15: =_xlfn.IFS(M15="integer","integer",M15="number","number",M15="boolean","boolean",TRUE,"string") -> string | O15: =_xlfn.IFS(M15="date","date",M15="markdown","markdown",M15="time", "time",M15="uri","uri",M15="uuid","uuid",TRUE,"") | S15: experiments
C16: ON | D16: common_technical_category | F16: 技術カテゴリー | G16: Technical Category | M16: string | N16: =_xlfn.IFS(M16="integer","integer",M16="number","number",M16="boolean","boolean",TRUE,"string") -> string | O16: =_xlfn.IFS(M16="date","date",M16="markdown","markdown",M16="time", "time",M16="uri","uri",M16="uuid","uuid",TRUE,"") | S16: measurement
C17: ON | D17: common_reference | F17: 参考文献 | G17: Reference | M17: string | N17: =_xlfn.IFS(M17="integer","integer",M17="number","number",M17="boolean","boolean",TRUE,"string") -> string | O17: =_xlfn.IFS(M17="date","date",M17="markdown","markdown",M17="time", "time",M17="uri","uri",M17="uuid","uuid",TRUE,"")
C18: ON | D18: property_property | F18: 特徴的性質 | G18: Property | M18: string | N18: =_xlfn.IFS(M18="integer","integer",M18="number","number",M18="boolean","boolean",TRUE,"string") -> string | O18: =_xlfn.IFS(M18="date","date",M18="markdown","markdown",M18="time", "time",M18="uri","uri",M18="uuid","uuid",TRUE,"") | S18: 磁性
C19: ON | D19: property_sub_category | F19: サブカテゴリー | G19: Sub category | M19: string | N19: =_xlfn.IFS(M19="integer","integer",M19="number","number",M19="boolean","boolean",TRUE,"string") -> string | O19: =_xlfn.IFS(M19="date","date",M19="markdown","markdown",M19="time", "time",M19="uri","uri",M19="uuid","uuid",TRUE,"") | S19: 飽和磁化
C20: ON | D20: measurement_method_category | F20: 計測法カテゴリー | G20: Method category | M20: string | N20: =_xlfn.IFS(M20="integer","integer",M20="number","number",M20="boolean","boolean",TRUE,"string") -> string | O20: =_xlfn.IFS(M20="date","date",M20="markdown","markdown",M20="time", "time",M20="uri","uri",M20="uuid","uuid",TRUE,"") | S20: 磁気特性
C21: ON | D21: measurement_method_sub_category | F21: 計測法サブカテゴリー | G21: Method sub-category | M21: string | N21: =_xlfn.IFS(M21="integer","integer",M21="number","number",M21="boolean","boolean",TRUE,"string") -> string | O21: =_xlfn.IFS(M21="date","date",M21="markdown","markdown",M21="time", "time",M21="uri","uri",M21="uuid","uuid",TRUE,"") | S21: 磁気特性測定システム
C22: ON | D22: measurement_analysis_field | F22: 分析分野 | G22: Analysis field | M22: string | N22: =_xlfn.IFS(M22="integer","integer",M22="number","number",M22="boolean","boolean",TRUE,"string") -> string | O22: =_xlfn.IFS(M22="date","date",M22="markdown","markdown",M22="time", "time",M22="uri","uri",M22="uuid","uuid",TRUE,"") | S22: 構造、微細組織、磁気特性
C23: ON | D23: measurement_measurement_environment | F23: 測定環境 | G23: Measurement environment | M23: string | N23: =_xlfn.IFS(M23="integer","integer",M23="number","number",M23="boolean","boolean",TRUE,"string") -> string | O23: =_xlfn.IFS(M23="date","date",M23="markdown","markdown",M23="time", "time",M23="uri","uri",M23="uuid","uuid",TRUE,"")
C24: ON | D24: measurement_energy_level_transition_structure_etc_of_interest | F24: 対象準位_遷移_構造 | G24: Energy Level_Transition_Structure etc. of interest | M24: string | N24: =_xlfn.IFS(M24="integer","integer",M24="number","number",M24="boolean","boolean",TRUE,"string") -> string | O24: =_xlfn.IFS(M24="date","date",M24="markdown","markdown",M24="time", "time",M24="uri","uri",M24="uuid","uuid",TRUE,"")
C25: ON | D25: measurement_measured_date | F25: 分析年月日 | G25: Measured date | M25: date | N25: =_xlfn.IFS(M25="integer","integer",M25="number","number",M25="boolean","boolean",TRUE,"string") -> string | O25: =_xlfn.IFS(M25="date","date",M25="markdown","markdown",M25="time", "time",M25="uri","uri",M25="uuid","uuid",TRUE,"") -> date
C26: ON | D26: measurement_standardized_procedure | F26: 標準手順 | G26: Standardized procedure | M26: string | N26: =_xlfn.IFS(M26="integer","integer",M26="number","number",M26="boolean","boolean",TRUE,"string") -> string | O26: =_xlfn.IFS(M26="date","date",M26="markdown","markdown",M26="time", "time",M26="uri","uri",M26="uuid","uuid",TRUE,"")
C27: ON | D27: measurement_instrumentation_site | F27: 装置設置場所 | G27: Instrumentation site | M27: string | N27: =_xlfn.IFS(M27="integer","integer",M27="number","number",M27="boolean","boolean",TRUE,"string") -> string | O27: =_xlfn.IFS(M27="date","date",M27="markdown","markdown",M27="time", "time",M27="uri","uri",M27="uuid","uuid",TRUE,"")
C28: OFF | M28: string | N28: =_xlfn.IFS(M28="integer","integer",M28="number","number",M28="boolean","boolean",TRUE,"string") -> string | O28: =_xlfn.IFS(M28="date","date",M28="markdown","markdown",M28="time", "time",M28="uri","uri",M28="uuid","uuid",TRUE,"") | P28: =_xlfn.IFS(M28="textarea","textarea",TRUE,"")
A29: sample_common | B29: 試料情報(共通項目) | C29: OFF | D29: sample_name_(local_id) | F29: 試料名(ローカルID) | G29: Sample name (Local ID)
C30: OFF | D30: chemical_formula_etc. | F30: 化学式・組成式・分子式など | G30: Chemical formula etc.
C31: OFF | D31: administrator_(affiliation) | F31: 試料管理者(所属) | G31: Administrator (Affiliation)
C32: OFF | D32: reference_url | F32: 参考URL | G32: Reference URL
C33: OFF | D33: related_samples | F33: 関連試料 | G33: Related samples
C34: OFF | D34: tags | F34: タグ | G34: Tags
C35: OFF | D35: description | F35: 試料の説明 | G35: Description
A36: sample_general | B36: 試料情報(一般項目) | C36: OFF | D36: =IFERROR(INDEX(sample.general_sample_term!A:H,MATCH($E36,sample.general_sample_term!C:C,FALSE),2),"") -> sample.general.general-name | E36: 一般名称 | F36: =IFERROR(INDEX(sample.general_sample_term!A:H,MATCH($E36,sample.general_sample_term!C:C,FALSE),3),"") -> 一般名称 | G36: =IFERROR(INDEX(sample.general_sample_term!A:H,MATCH($E36,sample.general_sample_term!C:C,FALSE),4),"") -> General name | U36: =IFERROR(INDEX(sample.general_sample_term!A:H,MATCH($E36,sample.general_sample_term!C:C,FALSE),5),"") -> 一般名称を入力してください | V36: =IFERROR(INDEX(sample.general_sample_term!A:H,MATCH($E36,sample.general_sample_term!C:C,FALSE),6),"") -> Please enter General name
C37: OFF | D37: =IFERROR(INDEX(sample.general_sample_term!A:H,MATCH($E37,sample.general_sample_term!C:C,FALSE),2),"") -> sample.general.cas-number | E37: CAS番号 | F37: =IFERROR(INDEX(sample.general_sample_term!A:H,MATCH($E37,sample.general_sample_term!C:C,FALSE),3),"") -> CAS番号 | G37: =IFERROR(INDEX(sample.general_sample_term!A:H,MATCH($E37,sample.general_sample_term!C:C,FALSE),4),"") -> CAS Number | U37: =IFERROR(INDEX(sample.general_sample_term!A:H,MATCH($E37,sample.general_sample_term!C:C,FALSE),5),"") -> CAS番号を入力してください | V37: =IFERROR(INDEX(sample.general_sample_term!A:H,MATCH($E37,sample.general_sample_term!C:C,FALSE),6),"") -> Please enter CAS Number
C38: OFF | D38: =IFERROR(INDEX(sample.general_sample_term!A:H,MATCH($E38,sample.general_sample_term!C:C,FALSE),2),"") -> sample.general.crystal-structure | E38: 結晶構造 | F38: =IFERROR(INDEX(sample.general_sample_term!A:H,MATCH($E38,sample.general_sample_term!C:C,FALSE),3),"") -> 結晶構造 | G38: =IFERROR(INDEX(sample.general_sample_term!A:H,MATCH($E38,sample.general_sample_term!C:C,FALSE),4),"") -> Crystal structure | U38: =IFERROR(INDEX(sample.general_sample_term!A:H,MATCH($E38,sample.general_sample_term!C:C,FALSE),5),"") -> 結晶構造を入力してください | V38: =IFERROR(INDEX(sample.general_sample_term!A:H,MATCH($E38,sample.general_sample_term!C:C,FALSE),6),"") -> Please enter Crystal structure
C39: OFF | D39: =IFERROR(INDEX(sample.general_sample_term!A:H,MATCH($E39,sample.general_sample_term!C:C,FALSE),2),"") -> sample.general.sample-shape | E39: 試料形状 | F39: =IFERROR(INDEX(sample.general_sample_term!A:H,MATCH($E39,sample.general_sample_term!C:C,FALSE),3),"") -> 試料形状 | G39: =IFERROR(INDEX(sample.general_sample_term!A:H,MATCH($E39,sample.general_sample_term!C:C,FALSE),4),"") -> Sample shape | U39: =IFERROR(INDEX(sample.general_sample_term!A:H,MATCH($E39,sample.general_sample_term!C:C,FALSE),5),"") -> 試料形状を入力してください | V39: =IFERROR(INDEX(sample.general_sample_term!A:H,MATCH($E39,sample.general_sample_term!C:C,FALSE),6),"") -> Please enter Sample shape
C40: OFF | D40: =IFERROR(INDEX(sample.general_sample_term!A:H,MATCH($E40,sample.general_sample_term!C:C,FALSE),2),"") -> sample.general.purchase-date | E40: 試料購入日 | F40: =IFERROR(INDEX(sample.general_sample_term!A:H,MATCH($E40,sample.general_sample_term!C:C,FALSE),3),"") -> 試料購入日 | G40: =IFERROR(INDEX(sample.general_sample_term!A:H,MATCH($E40,sample.general_sample_term!C:C,FALSE),4),"") -> Purchase date | U40: =IFERROR(INDEX(sample.general_sample_term!A:H,MATCH($E40,sample.general_sample_term!C:C,FALSE),5),"") -> 試料購入日を入力してください | V40: =IFERROR(INDEX(sample.general_sample_term!A:H,MATCH($E40,sample.general_sample_term!C:C,FALSE),6),"") -> Please enter Purchase date
C41: OFF | D41: =IFERROR(INDEX(sample.general_sample_term!A:H,MATCH($E41,sample.general_sample_term!C:C,FALSE),2),"") -> sample.general.supplier | E41: 購入元 | F41: =IFERROR(INDEX(sample.general_sample_term!A:H,MATCH($E41,sample.general_sample_term!C:C,FALSE),3),"") -> 購入元 | G41: =IFERROR(INDEX(sample.general_sample_term!A:H,MATCH($E41,sample.general_sample_term!C:C,FALSE),4),"") -> Supplier | U41: =IFERROR(INDEX(sample.general_sample_term!A:H,MATCH($E41,sample.general_sample_term!C:C,FALSE),5),"") | V41: =IFERROR(INDEX(sample.general_sample_term!A:H,MATCH($E41,sample.general_sample_term!C:C,FALSE),6),"")
...

Sheet 要件定義(catalog.schema.json)
A1: $schema | B1: https://json-schema.org/draft/2020-12/schema
A2: $id | B2: ="https://rde.nims.go.jp/rde/dataset-templates/"&説明!B3&"/catalog.schema.json" -> https://rde.nims.go.jp/rde/dataset-templates/RDEDatasetTemplateSheet_RDE_VSM_mpms/catalog.schema.json
A3: description | B3: =説明!B4&": データカタログ定義" -> 標準データセットテンプレートRDE_VSM_mpms用RDEデータセットテンプレート: データカタログ定義
A4: title/ja | B4: =説明!B1&":データカタログ定義" -> RDEDatasetTemplateSheet_RDE_VSM_mpms:データカタログ定義
A5: title/en | B5: =説明!B2&":data catalog format" -> RDEDatasetTemplateSheet_RDE_VSM_mpms:data catalog format
A7: header | B7: output | C7: parameter_name | D7: label/ja | E7: label/en | F7: required | G7: typeformat | H7: type | I7: format | J7: options/widget | K7: options/rows | L7: enum | M7: description | N7: examples | O7: default | P7: const | Q7: options/unit | R7: options/placeholder/ja | S7: options/placeholder/en | T7: maximum | U7: exclusiveMaximum | V7: minimum | W7: exclusiveMinimum | X7: maxLength | Y7: minLength | Z7: pattern
A8: ヘッダー | B8: 出力制御 (必ず選択) | C8: パラメータ名 (必ず記述) | D8: 項目名(日本語) (必ず記述) | E8: 項目名(英語) (必ず記述) | F8: 必須項目 (選択リスト） | G8: データ形式 (必ず選択) | H8: データ型 (自動入力） | I8: フォーマット (自動入力） | J8: テキストエリア (自動入力） | K8: 行数 (数値記述） | L8: 値のリスト (カンマ区切り） | M8: 説明 (自由記述） | N8: 内容サンプル (自由記述） | O8: 初期値 (自由記述） | P8: 固定値 (自由記述） | Q8: 単位 (自由記述） | R8: プレイスホルダ(日本語) (自由記述） | S8: プレイスホルダ(英語) (自由記述） | T8: 数値上限(以下) (数値記述） | U8: 数値上限(未満) (数値記述） | V8: 数値下限(以上) (数値記述） | W8: 数値下限(より上) (数値記述） | X8: 最大文字数 (数値記述） | Y8: 最小文字数 (数値記述） | Z8: 正規表現 (自由記述）
A9: data_catalog | B9: ON | C9: dataset_title | D9: データセット名 | E9: Dataset Title | G9: string | H9: =_xlfn.IFS(G9="integer","integer",G9="number","number",G9="boolean","boolean",TRUE,"string") -> string | I9: =_xlfn.IFS(G9="date","date",G9="markdown","markdown",G9="time", "time",G9="uri","uri",G9="uuid","uuid",TRUE,"") | J9: =_xlfn.IFS(G9="textarea","textarea",TRUE,"") | N9: dtaset_title
B10: ON | C10: data_creator | D10: 作成者 | E10: Data Creator | G10: string | H10: =_xlfn.IFS(G10="integer","integer",G10="number","number",G10="boolean","boolean",TRUE,"string") -> string | I10: =_xlfn.IFS(G10="date","date",G10="markdown","markdown",G10="time", "time",G10="uri","uri",G10="uuid","uuid",TRUE,"") | J10: =_xlfn.IFS(G10="textarea","textarea",TRUE,"") | N10: data_creator
B11: ON | C11: experimental_apparatus | D11: 使用装置 | E11: Experimental Apparatus | G11: textarea | H11: =_xlfn.IFS(G11="integer","integer",G11="number","number",G11="boolean","boolean",TRUE,"string") -> string | I11: =_xlfn.IFS(G11="date","date",G11="markdown","markdown",G11="time", "time",G11="uri","uri",G11="uuid","uuid",TRUE,"") | J11: =_xlfn.IFS(G11="textarea","textarea",TRUE,"") -> textarea | K11: 2 | N11: experimental_apparatus
B12: ON | C12: data_distribution | D12: データの再配布 | E12: Data Distribution | G12: textarea | H12: =_xlfn.IFS(G12="integer","integer",G12="number","number",G12="boolean","boolean",TRUE,"string") -> string | I12: =_xlfn.IFS(G12="date","date",G12="markdown","markdown",G12="time", "time",G12="uri","uri",G12="uuid","uuid",TRUE,"") | J12: =_xlfn.IFS(G12="textarea","textarea",TRUE,"") -> textarea | K12: 5 | N12: data_distribution
B13: ON | C13: raw_data_type | D13: データの種類 | E13: Raw Data Type | G13: textarea | H13: =_xlfn.IFS(G13="integer","integer",G13="number","number",G13="boolean","boolean",TRUE,"string") -> string | I13: =_xlfn.IFS(G13="date","date",G13="markdown","markdown",G13="time", "time",G13="uri","uri",G13="uuid","uuid",TRUE,"") | J13: =_xlfn.IFS(G13="textarea","textarea",TRUE,"") -> textarea | K13: 5 | N13: raw_data_type
B14: ON | C14: stored_data | D14: 格納データ | E14: Stored Data | G14: textarea | H14: =_xlfn.IFS(G14="integer","integer",G14="number","number",G14="boolean","boolean",TRUE,"string") -> string | I14: =_xlfn.IFS(G14="date","date",G14="markdown","markdown",G14="time", "time",G14="uri","uri",G14="uuid","uuid",TRUE,"") | J14: =_xlfn.IFS(G14="textarea","textarea",TRUE,"") -> textarea | K14: 5 | N14: stored_data
B15: ON | C15: remarks | D15: 備考 | E15: Remarks | G15: textarea | H15: =_xlfn.IFS(G15="integer","integer",G15="number","number",G15="boolean","boolean",TRUE,"string") -> string | I15: =_xlfn.IFS(G15="date","date",G15="markdown","markdown",G15="time", "time",G15="uri","uri",G15="uuid","uuid",TRUE,"") | J15: =_xlfn.IFS(G15="textarea","textarea",TRUE,"") -> textarea | K15: 5 | N15: remarks
B16: ON | C16: references | D16: 参考文献 | E16: References | G16: textarea | H16: =_xlfn.IFS(G16="integer","integer",G16="number","number",G16="boolean","boolean",TRUE,"string") -> string | I16: =_xlfn.IFS(G16="date","date",G16="markdown","markdown",G16="time", "time",G16="uri","uri",G16="uuid","uuid",TRUE,"") | J16: =_xlfn.IFS(G16="textarea","textarea",TRUE,"") -> textarea | K16: 5 | N16: references
B17: OFF | G17: string | H17: =_xlfn.IFS(G17="integer","integer",G17="number","number",G17="boolean","boolean",TRUE,"string") -> string | I17: =_xlfn.IFS(G17="date","date",G17="markdown","markdown",G17="time", "time",G17="uri","uri",G17="uuid","uuid",TRUE,"") | J17: =_xlfn.IFS(G17="textarea","textarea",TRUE,"") | K17: 3
B18: OFF | G18: string | H18: =_xlfn.IFS(G18="integer","integer",G18="number","number",G18="boolean","boolean",TRUE,"string") -> string | I18: =_xlfn.IFS(G18="date","date",G18="markdown","markdown",G18="time", "time",G18="uri","uri",G18="uuid","uuid",TRUE,"") | J18: =_xlfn.IFS(G18="textarea","textarea",TRUE,"")

Sheet dict.term
A1: id | B1: name_ja | C1: name_en | D1: hint_ja | E1: hint_en | F1: term_uri | G1: created
A2: 2f815032-c60b-2c42-46dd-cdb4624ede4b | B2: 計測装置 | C2: Characterization Instrument | F2: https://matvoc.nims.go.jp/entity/Q1885 | G2: 2022-07-11 04:36:42.734137+00
A3: 2f7cdff7-bc05-6fb3-3d5e-30827a252aaa | B3: 磁気共鳴 | C3: Magnetic Resonance | F3: https://matvoc.nims.go.jp/entity/Q1888 | G3: 2022-07-11 04:36:42.734137+00
A4: e6bbc4b0-a89c-a7d9-65b3-08777b320816 | B4: 核磁気共鳴装置 | C4: Nuclear Magnetic Resonance | F4: https://matvoc.nims.go.jp/entity/Q2116 | G4: 2022-07-11 04:36:42.734137+00
A5: 9cac4bf4-b310-6840-499d-59dd515b5ab5 | B5: 磁気共鳴画像診断 | C5: Magnetic Resonance Imaging | F5: https://matvoc.nims.go.jp/entity/Q2117 | G5: 2022-07-11 04:36:42.734137+00
A6: 6268c0bb-2636-4769-6ab0-a06ae0d03b61 | B6: 電子スピン共鳴 | C6: Electron Spin Resonance | F6: https://matvoc.nims.go.jp/entity/Q2118 | G6: 2022-07-11 04:36:42.734137+00
A7: 388d9707-6c0f-3f0b-3770-c8959e21614b | B7: 電子顕微鏡 | C7: Electron Microscope | F7: https://matvoc.nims.go.jp/entity/Q1923 | G7: 2022-07-11 04:36:42.734137+00
A8: b46a3376-3789-9ed3-d3a3-bff79de11501 | B8: 透過型電子顕微鏡 | C8: Transmission Electron Microscope | F8: https://matvoc.nims.go.jp/entity/Q2119 | G8: 2022-07-11 04:36:42.734137+00
A9: 1359fc21-f043-ccdf-7d12-33117909f55f | B9: 走査型透過電子顕微鏡 | C9: Scanning Transmission Electron Microscope | F9: https://matvoc.nims.go.jp/entity/Q2120 | G9: 2022-07-11 04:36:42.734137+00
A10: ae9aa759-1af2-2155-654f-c8a2bacba3f9 | B10: 走査型電子顕微鏡 | C10: Scannning Electron Microscope | F10: https://matvoc.nims.go.jp/entity/Q2121 | G10: 2022-07-11 04:36:42.734137+00
A11: b4f9c6b7-8b98-bef0-3148-b65bc67cf333 | B11: 超高圧電子顕微鏡 | C11: Ultra-high Voltage Electron Microscope | F11: https://matvoc.nims.go.jp/entity/Q2122 | G11: 2022-07-11 04:36:42.734137+00
A12: c611ca1d-9001-8c1f-d450-2542698c3d05 | B12: クライオ電子顕微鏡 | C12: Cryo-Electron Microscope | F12: https://matvoc.nims.go.jp/entity/Q2123 | G12: 2022-07-11 04:36:42.734137+00
A13: b941b1db-8b17-69c8-2129-92f48dfe26f8 | B13: 三次元電子顕微鏡 | C13: 3D Electron Microscope | F13: https://matvoc.nims.go.jp/entity/Q2124 | G13: 2022-07-11 04:36:42.734137+00
... A347: 4a684b87-c1db-005f-9935-f75b4e2f9056 | B347: 撹拌機 | C347: Stirrer | F347: https://matvoc.nims.go.jp/entity/Q2071 | G347: 2022-07-11 04:36:42.734137+00
A348: 33c6e9dc-5787-0f96-7683-f39281c60419 | B348: 化学式、組成式、分子式など | C348: Chemical formula, composition formula, molecular formula, etc. | D348: 化学式、組成式、分子式などを入力してください | E348: Please enter Chemical formula, composition formula, molecular formula, etc. | F348: NULL | G348: 2022-07-11 04:36:42.734137+00
A349: f2d5e89e-01f0-66a2-5d8e-623a4fc31698 | B349: 物質名 | C349: Material name | D349: 物質名を入力してください | E349: Please enter Material name | F349: NULL | G349: 2022-07-11 04:36:42.734137+00
A350: a7a6fc7b-ed46-88b0-bba8-a1e34857a049 | B350: 試料別名 | C350: Another sample name | D350: 試料別名を入力してください | E350: Please enter Another sample name | F350: NULL | G350: 2022-07-11 04:36:42.734137+00
A351: f207e704-9308-42f0-b090-98e2db81c757 | B351: グロー放電質量分析法 | C351: Glow Discharge Mass Spectrometry | D351: NULL | E351: NULL | F351: https://matvoc.nims.go.jp/entity/Q2839 | G351: 2022-09-05 04:02:31.114117+00
A352: 0d0417a3-3c3b-496a-b0fb-5a26f8a74166 | B352: ロット番号、製造番号など | C352: Lot number or product number etc | F352: NULL | G352: 2022-10-11 06:13:06.860778+00
A353: e2d20d02-2e38-2cd3-b1b3-66fdb8a11057 | B353: CAS番号 | C353: CAS Number | D353: CAS番号を入力してください | E353: Please enter CAS Number | F353: NULL | G353: 2022-07-11 04:36:42.734137+00
A354: 1e70d11d-cbdd-bfd1-9301-9612c29b4060 | B354: 試料購入日 | C354: Purchase date | D354: 試料購入日を入力してください | E354: Please enter Purchase date | F354: NULL | G354: 2022-07-11 04:36:42.734137+00
A355: 1d3cab05-3eaa-cb9b-9a3f-20eb0ca26963 | B355: 結晶状態 | C355: Crystalline state | D355: 結晶状態を入力してください | E355: Please enter Crystalline state | F355: NULL | G355: 2022-07-11 04:36:42.734137+00
A356: efcf34e7-4308-c195-6691-6f4d28ffc9bb | B356: 結晶構造 | C356: Crystal structure | D356: 結晶構造を入力してください | E356: Please enter Crystal structure | F356: NULL | G356: 2022-07-11 04:36:42.734137+00
A357: e9617207-7f74-ef45-9b05-74eef6e4ecbb | B357: ピアソン記号 | C357: Pearson symbol | D357: ピアソン記号を入力してください | E357: Please enter Pearson symbol | F357: NULL | G357: 2022-07-11 04:36:42.734137+00
A358: f63149a4-e57c-4273-4c1e-dffa41356d28 | B358: 空間群 | C358: Space group | D358: 空間群を入力してください | E358: Please enter Space group | F358: https://matvoc.nims.go.jp/wiki/Item:Q224 | G358: 2022-07-11 04:36:42.734137+00
A359: 7cc57dfb-8b70-4b3a-5315-fbce4cbf73d0 | B359: 試料形状 | C359: Sample shape | D359: 試料形状を入力してください | E359: Please enter Sample shape | F359: NULL | G359: 2022-07-11 04:36:42.734137+00
A360: 3250c45d-0ed6-1438-43b5-eb679918604a | B360: 化学式 | C360: Chemical formula | D360: 化学式を入力してください | E360: Please enter Chemical formula | F360: NULL | G360: 2022-07-11 04:36:42.734137+00
A361: 70c2c751-5404-19b7-4a5e-981e6cebbb15 | B361: 名称 | C361: Name | D361: 名称を入力してください | E361: Please enter Name | F361: NULL | G361: 2022-07-11 04:36:42.734137+00
A362: 518e26a0-4262-86f5-3598-80e18e6ff2af | B362: PubChem | C362: PubChem | D362: PubChemを入力してください | E362: Please enter PubChem | F362: NULL | G362: 2022-07-11 04:36:42.734137+00
A363: 3a775d54-5c13-fe66-6405-29c05bc931ce | B363: 粘度 | C363: viscosity | D363: 粘度を入力してください | E363: Please enter viscosity | F363: https://matvoc.nims.go.jp/wiki/Item:Q284 | G363: 2022-07-11 04:36:42.734137+00
A364: 659da80e-c2ee-2986-41ce-68201b3bc4dd | B364: 沸点 | C364: boiling point | D364: 沸点を入力してください | E364: Please enter boiling point | F364: NULL | G364: 2022-07-11 04:36:42.734137+00
... A376: 9270879d-d94e-4d3f-2d5c-19568e040004 | B376: InChI | C376: InChI | D376: InChIを入力してください | E376: Please enter InChI | F376: NULL | G376: 2022-08-01 09:32:47.462801+00

Sheet sample.general_sample_term
A1: term_id | B1: key_name | C1: dict.term.name_ja | D1: dict.term.name_en | E1: dict.term.hint_ja | F1: dict.term.hint_en | G1: dict.term.term_uri | H1: dict.term.created
A2: 33c6e9dc-5787-0f96-7683-f39281c60419 | B2: sample.general.composiiton | C2: =VLOOKUP(A2,dict.term!A:G,2,FALSE)&"" -> 化学式、組成式、分子式など | D2: =VLOOKUP(A2,dict.term!A:G,3,FALSE)&"" -> Chemical formula, composition formula, molecular formula, etc. | E2: =VLOOKUP(A2,dict.term!A:G,4,FALSE)&"" -> 化学式、組成式、分子式などを入力してください | F2: =VLOOKUP(A2,dict.term!A:G,5,FALSE)&"" -> Please enter Chemical formula, composition formula, molecular formula, etc. | G2: =VLOOKUP(A2,dict.term!A:G,6,FALSE)&"" -> NULL | H2: =VLOOKUP(A2,dict.term!A:G,7,FALSE)&"" -> 2022-07-11 04:36:42.734137+00
A3: f2d5e89e-01f0-66a2-5d8e-623a4fc31698 | B3: sample.general.material-name | C3: =VLOOKUP(A3,dict.term!A:G,2,FALSE)&"" -> 物質名 | D3: =VLOOKUP(A3,dict.term!A:G,3,FALSE)&"" -> Material name | E3: =VLOOKUP(A3,dict.term!A:G,4,FALSE)&"" -> 物質名を入力してください | F3: =VLOOKUP(A3,dict.term!A:G,5,FALSE)&"" -> Please enter Material name | G3: =VLOOKUP(A3,dict.term!A:G,6,FALSE)&"" -> NULL | H3: =VLOOKUP(A3,dict.term!A:G,7,FALSE)&"" -> 2022-07-11 04:36:42.734137+00
A4: a7a6fc7b-ed46-88b0-bba8-a1e34857a049 | B4: sample.general.sample-alias | C4: =VLOOKUP(A4,dict.term!A:G,2,FALSE)&"" -> 試料別名 | D4: =VLOOKUP(A4,dict.term!A:G,3,FALSE)&"" -> Another sample name | E4: =VLOOKUP(A4,dict.term!A:G,4,FALSE)&"" -> 試料別名を入力してください | F4: =VLOOKUP(A4,dict.term!A:G,5,FALSE)&"" -> Please enter Another sample name | G4: =VLOOKUP(A4,dict.term!A:G,6,FALSE)&"" -> NULL | H4: =VLOOKUP(A4,dict.term!A:G,7,FALSE)&"" -> 2022-07-11 04:36:42.734137+00
A5: e2d20d02-2e38-2cd3-b1b3-66fdb8a11057 | B5: sample.general.cas-number | C5: =VLOOKUP(A5,dict.term!A:G,2,FALSE)&"" -> CAS番号 | D5: =VLOOKUP(A5,dict.term!A:G,3,FALSE)&"" -> CAS Number | E5: =VLOOKUP(A5,dict.term!A:G,4,FALSE)&"" -> CAS番号を入力してください | F5: =VLOOKUP(A5,dict.term!A:G,5,FALSE)&"" -> Please enter CAS Number | G5: =VLOOKUP(A5,dict.term!A:G,6,FALSE)&"" -> NULL | H5: =VLOOKUP(A5,dict.term!A:G,7,FALSE)&"" -> 2022-07-11 04:36:42.734137+00
A6: 1e70d11d-cbdd-bfd1-9301-9612c29b4060 | B6: sample.general.purchase-date | C6: =VLOOKUP(A6,dict.term!A:G,2,FALSE)&"" -> 試料購入日 | D6: =VLOOKUP(A6,dict.term!A:G,3,FALSE)&"" -> Purchase date | E6: =VLOOKUP(A6,dict.term!A:G,4,FALSE)&"" -> 試料購入日を入力してください | F6: =VLOOKUP(A6,dict.term!A:G,5,FALSE)&"" -> Please enter Purchase date | G6: =VLOOKUP(A6,dict.term!A:G,6,FALSE)&"" -> NULL | H6: =VLOOKUP(A6,dict.term!A:G,7,FALSE)&"" -> 2022-07-11 04:36:42.734137+00
A7: 1d3cab05-3eaa-cb9b-9a3f-20eb0ca26963 | B7: sample.general.crystalline-state | C7: =VLOOKUP(A7,dict.term!A:G,2,FALSE)&"" -> 結晶状態 | D7: =VLOOKUP(A7,dict.term!A:G,3,FALSE)&"" -> Crystalline state | E7: =VLOOKUP(A7,dict.term!A:G,4,FALSE)&"" -> 結晶状態を入力してください | F7: =VLOOKUP(A7,dict.term!A:G,5,FALSE)&"" -> Please enter Crystalline state | G7: =VLOOKUP(A7,dict.term!A:G,6,FALSE)&"" -> NULL | H7: =VLOOKUP(A7,dict.term!A:G,7,FALSE)&"" -> 2022-07-11 04:36:42.734137+00
A8: efcf34e7-4308-c195-6691-6f4d28ffc9bb | B8: sample.general.crystal-structure | C8: =VLOOKUP(A8,dict.term!A:G,2,FALSE)&"" -> 結晶構造 | D8: =VLOOKUP(A8,dict.term!A:G,3,FALSE)&"" -> Crystal structure | E8: =VLOOKUP(A8,dict.term!A:G,4,FALSE)&"" -> 結晶構造を入力してください | F8: =VLOOKUP(A8,dict.term!A:G,5,FALSE)&"" -> Please enter Crystal structure | G8: =VLOOKUP(A8,dict.term!A:G,6,FALSE)&"" -> NULL | H8: =VLOOKUP(A8,dict.term!A:G,7,FALSE)&"" -> 2022-07-11 04:36:42.734137+00
A9: e9617207-7f74-ef45-9b05-74eef6e4ecbb | B9: sample.general.pearson-symbol | C9: =VLOOKUP(A9,dict.term!A:G,2,FALSE)&"" -> ピアソン記号 | D9: =VLOOKUP(A9,dict.term!A:G,3,FALSE)&"" -> Pearson symbol | E9: =VLOOKUP(A9,dict.term!A:G,4,FALSE)&"" -> ピアソン記号を入力してください | F9: =VLOOKUP(A9,dict.term!A:G,5,FALSE)&"" -> Please enter Pearson symbol | G9: =VLOOKUP(A9,dict.term!A:G,6,FALSE)&"" -> NULL | H9: =VLOOKUP(A9,dict.term!A:G,7,FALSE)&"" -> 2022-07-11 04:36:42.734137+00
A10: f63149a4-e57c-4273-4c1e-dffa41356d28 | B10: sample.general.space-group | C10: =VLOOKUP(A10,dict.term!A:G,2,FALSE)&"" -> 空間群 | D10: =VLOOKUP(A10,dict.term!A:G,3,FALSE)&"" -> Space group | E10: =VLOOKUP(A10,dict.term!A:G,4,FALSE)&"" -> 空間群を入力してください | F10: =VLOOKUP(A10,dict.term!A:G,5,FALSE)&"" -> Please enter Space group | G10: =VLOOKUP(A10,dict.term!A:G,6,FALSE)&"" -> https://matvoc.nims.go.jp/wiki/Item:Q224 | H10: =VLOOKUP(A10,dict.term!A:G,7,FALSE)&"" -> 2022-07-11 04:36:42.734137+00
A11: 7cc57dfb-8b70-4b3a-5315-fbce4cbf73d0 | B11: sample.general.sample-shape | C11: =VLOOKUP(A11,dict.term!A:G,2,FALSE)&"" -> 試料形状 | D11: =VLOOKUP(A11,dict.term!A:G,3,FALSE)&"" -> Sample shape | E11: =VLOOKUP(A11,dict.term!A:G,4,FALSE)&"" -> 試料形状を入力してください | F11: =VLOOKUP(A11,dict.term!A:G,5,FALSE)&"" -> Please enter Sample shape | G11: =VLOOKUP(A11,dict.term!A:G,6,FALSE)&"" -> NULL | H11: =VLOOKUP(A11,dict.term!A:G,7,FALSE)&"" -> 2022-07-11 04:36:42.734137+00
A12: efc6a0d5-313e-1871-190c-baaff7d1bf6c | B12: sample.general.smiles-string | C12: =VLOOKUP(A12,dict.term!A:G,2,FALSE)&"" -> SMILES String | D12: =VLOOKUP(A12,dict.term!A:G,3,FALSE)&"" -> SMILES String | E12: =VLOOKUP(A12,dict.term!A:G,4,FALSE)&"" -> SMILES Stringを入力してください | F12: =VLOOKUP(A12,dict.term!A:G,5,FALSE)&"" -> Please enter SMILES String | G12: =VLOOKUP(A12,dict.term!A:G,6,FALSE)&"" -> NULL | H12: =VLOOKUP(A12,dict.term!A:G,7,FALSE)&"" -> 2022-08-01 09:32:47.462801+00
A13: 9270879d-d94e-4d3f-2d5c-19568e040004 | B13: sample.general.inchi | C13: =VLOOKUP(A13,dict.term!A:G,2,FALSE)&"" -> InChI | D13: =VLOOKUP(A13,dict.term!A:G,3,FALSE)&"" -> InChI | E13: =VLOOKUP(A13,dict.term!A:G,4,FALSE)&"" -> InChIを入力してください | F13: =VLOOKUP(A13,dict.term!A:G,5,FALSE)&"" -> Please enter InChI | G13: =VLOOKUP(A13,dict.term!A:G,6,FALSE)&"" -> NULL | H13: =VLOOKUP(A13,dict.term!A:G,7,FALSE)&"" -> 2022-08-01 09:32:47.462801+00
... A25: 0d0417a3-3c3b-496a-b0fb-5a26f8a74166 | B25: sample.general.lot-number-or-product-number-etc | C25: =VLOOKUP(A25,dict.term!A:G,2,FALSE)&"" -> ロット番号、製造番号など | D25: =VLOOKUP(A25,dict.term!A:G,3,FALSE)&"" -> Lot number or product number etc | E25: =VLOOKUP(A25,dict.term!A:G,4,FALSE)&"" | F25: =VLOOKUP(A25,dict.term!A:G,5,FALSE)&"" | G25: =VLOOKUP(A25,dict.term!A:G,6,FALSE)&"" -> NULL | H25: =VLOOKUP(A25,dict.term!A:G,7,FALSE)&"" -> 2022-10-11 06:13:06.860778+00

Sheet sample.sample_class
A1: id | B1: name_ja | C1: name_en
A2: 01cb3c01-37a4-5a43-d8ca-f523ca99a75b | B2: 有機材料 | C2: organic material
A3: 932e4fe1-9724-305f-ffc5-1908c31c83e5 | B3: 無機材料 | C3: inorganic material
A4: a674a8ef-efa8-9497-4ed4-74de55fafddb | B4: 金属・合金 | C4: metals and alloys
A5: 342ba516-4d02-171c-9bc4-70a3134b47a8 | B5: ポリマー | C5: polymers
A6: 52148afb-6759-23e8-c8b8-33912ec5bfcf | B6: 半導体 | C6: semiconductors
A7: 961c9637-9b83-0e9d-e60e-ffc1e2517afd | B7: セラミックス | C7: ceramics
A8: 0dde5969-3039-739b-b33b-97df40450790 | B8: 生物学的物質 | C8: biological

Sheet sample.specific_sample_term
A1: sample_class_id | B1: term_id | C1: key_name | D1: sample.sample_class.name_ja | E1: sample.sample_class.name_en | F1: dict.term.name_ja | G1: dict.term.name_en | H1: dict.term.hint_ja | I1: dict.term.hint_en | J1: dict.term.term_uri | K1: dict.term.created | L1: bind_class_and_term_ja | M1: bind_class_and_term_en
A2: 01cb3c01-37a4-5a43-d8ca-f523ca99a75b | B2: 3250c45d-0ed6-1438-43b5-eb679918604a | C2: sample.specific.organic.chemical-formula | D2: =VLOOKUP(A2,sample.sample_class!A:C,2,FALSE)&"" -> 有機材料 | E2: =VLOOKUP(A2,sample.sample_class!A:C,3,FALSE)&"" -> organic material | F2: =VLOOKUP(B2,dict.term!A:G,2,FALSE)&"" -> 化学式 | G2: =VLOOKUP(B2,dict.term!A:G,3,FALSE)&"" -> Chemical formula | H2: =VLOOKUP(B2,dict.term!A:G,4,FALSE)&"" -> 化学式を入力してください | I2: =VLOOKUP(B2,dict.term!A:G,5,FALSE)&"" -> Please enter Chemical formula | J2: =VLOOKUP(B2,dict.term!A:G,6,FALSE)&"" -> NULL | K2: =VLOOKUP(B2,dict.term!A:G,7,FALSE)&"" -> 2022-07-11 04:36:42.734137+00 | L2: =D2&"/"&F2 -> 有機材料/化学式 | M2: =E2&"/"&G2 -> organic material/Chemical formula
A3: 01cb3c01-37a4-5a43-d8ca-f523ca99a75b | B3: 70c2c751-5404-19b7-4a5e-981e6cebbb15 | C3: sample.specific.organic.name | D3: =VLOOKUP(A3,sample.sample_class!A:C,2,FALSE)&"" -> 有機材料 | E3: =VLOOKUP(A3,sample.sample_class!A:C,3,FALSE)&"" -> organic material | F3: =VLOOKUP(B3,dict.term!A:G,2,FALSE)&"" -> 名称 | G3: =VLOOKUP(B3,dict.term!A:G,3,FALSE)&"" -> Name | H3: =VLOOKUP(B3,dict.term!A:G,4,FALSE)&"" -> 名称を入力してください | I3: =VLOOKUP(B3,dict.term!A:G,5,FALSE)&"" -> Please enter Name | J3: =VLOOKUP(B3,dict.term!A:G,6,FALSE)&"" -> NULL | K3: =VLOOKUP(B3,dict.term!A:G,7,FALSE)&"" -> 2022-07-11 04:36:42.734137+00 | L3: =D3&"/"&F3 -> 有機材料/名称 | M3: =E3&"/"&G3 -> organic material/Name
A4: 01cb3c01-37a4-5a43-d8ca-f523ca99a75b | B4: e2d20d02-2e38-2cd3-b1b3-66fdb8a11057 | C4: sample.specific.organic.cas-number | D4: =VLOOKUP(A4,sample.sample_class!A:C,2,FALSE)&"" -> 有機材料 | E4: =VLOOKUP(A4,sample.sample_class!A:C,3,FALSE)&"" -> organic material | F4: =VLOOKUP(B4,dict.term!A:G,2,FALSE)&"" -> CAS番号 | G4: =VLOOKUP(B4,dict.term!A:G,3,FALSE)&"" -> CAS Number | H4: =VLOOKUP(B4,dict.term!A:G,4,FALSE)&"" -> CAS番号を入力してください | I4: =VLOOKUP(B4,dict.term!A:G,5,FALSE)&"" -> Please enter CAS Number | J4: =VLOOKUP(B4,dict.term!A:G,6,FALSE)&"" -> NULL | K4: =VLOOKUP(B4,dict.term!A:G,7,FALSE)&"" -> 2022-07-11 04:36:42.734137+00 | L4: =D4&"/"&F4 -> 有機材料/CAS番号 | M4: =E4&"/"&G4 -> organic material/CAS Number
A5: 01cb3c01-37a4-5a43-d8ca-f523ca99a75b | B5: 518e26a0-4262-86f5-3598-80e18e6ff2af | C5: sample.specific.organic.pubchem | D5: =VLOOKUP(A5,sample.sample_class!A:C,2,FALSE)&"" -> 有機材料 | E5: =VLOOKUP(A5,sample.sample_class!A:C,3,FALSE)&"" -> organic material | F5: =VLOOKUP(B5,dict.term!A:G,2,FALSE)&"" -> PubChem | G5: =VLOOKUP(B5,dict.term!A:G,3,FALSE)&"" -> PubChem | H5: =VLOOKUP(B5,dict.term!A:G,4,FALSE)&"" -> PubChemを入力してください | I5: =VLOOKUP(B5,dict.term!A:G,5,FALSE)&"" -> Please enter PubChem | J5: =VLOOKUP(B5,dict.term!A:G,6,FALSE)&"" -> NULL | K5: =VLOOKUP(B5,dict.term!A:G,7,FALSE)&"" -> 2022-07-11 04:36:42.734137+00 | L5: =D5&"/"&F5 -> 有機材料/PubChem | M5: =E5&"/"&G5 -> organic material/PubChem
A6: 01cb3c01-37a4-5a43-d8ca-f523ca99a75b | B6: 3a775d54-5c13-fe66-6405-29c05bc931ce | C6: sample.specific.organic.viscosity | D6: =VLOOKUP(A6,sample.sample_class!A:C,2,FALSE)&"" -> 有機材料 | E6: =VLOOKUP(A6,sample.sample_class!A:C,3,FALSE)&"" -> organic material | F6: =VLOOKUP(B6,dict.term!A:G,2,FALSE)&"" -> 粘度 | G6: =VLOOKUP(B6,dict.term!A:G,3,FALSE)&"" -> viscosity | H6: =VLOOKUP(B6,dict.term!A:G,4,FALSE)&"" -> 粘度を入力してください | I6: =VLOOKUP(B6,dict.term!A:G,5,FALSE)&"" -> Please enter viscosity | J6: =VLOOKUP(B6,dict.term!A:G,6,FALSE)&"" -> https://matvoc.nims.go.jp/wiki/Item:Q284 | K6: =VLOOKUP(B6,dict.term!A:G,7,FALSE)&"" -> 2022-07-11 04:36:42.734137+00 | L6: =D6&"/"&F6 -> 有機材料/粘度 | M6: =E6&"/"&G6 -> organic material/viscosity
A7: 01cb3c01-37a4-5a43-d8ca-f523ca99a75b | B7: 659da80e-c2ee-2986-41ce-68201b3bc4dd | C7: sample.specific.organic.boiling-point | D7: =VLOOKUP(A7,sample.sample_class!A:C,2,FALSE)&"" -> 有機材料 | E7: =VLOOKUP(A7,sample.sample_class!A:C,3,FALSE)&"" -> organic material | F7: =VLOOKUP(B7,dict.term!A:G,2,FALSE)&"" -> 沸点 | G7: =VLOOKUP(B7,dict.term!A:G,3,FALSE)&"" -> boiling point | H7: =VLOOKUP(B7,dict.term!A:G,4,FALSE)&"" -> 沸点を入力してください | I7: =VLOOKUP(B7,dict.term!A:G,5,FALSE)&"" -> Please enter boiling point | J7: =VLOOKUP(B7,dict.term!A:G,6,FALSE)&"" -> NULL | K7: =VLOOKUP(B7,dict.term!A:G,7,FALSE)&"" -> 2022-07-11 04:36:42.734137+00 | L7: =D7&"/"&F7 -> 有機材料/沸点 | M7: =E7&"/"&G7 -> organic material/boiling point
A8: 01cb3c01-37a4-5a43-d8ca-f523ca99a75b | B8: 4efc4c3b-727c-c752-cf28-701b55dba1af | C8: sample.specific.organic.melting-temperature | D8: =VLOOKUP(A8,sample.sample_class!A:C,2,FALSE)&"" -> 有機材料 | E8: =VLOOKUP(A8,sample.sample_class!A:C,3,FALSE)&"" -> organic material | F8: =VLOOKUP(B8,dict.term!A:G,2,FALSE)&"" -> 融点 | G8: =VLOOKUP(B8,dict.term!A:G,3,FALSE)&"" -> Melting temperature | H8: =VLOOKUP(B8,dict.term!A:G,4,FALSE)&"" -> 融点を入力してください | I8: =VLOOKUP(B8,dict.term!A:G,5,FALSE)&"" -> Please enter Melting temperature | J8: =VLOOKUP(B8,dict.term!A:G,6,FALSE)&"" -> https://matvoc.nims.go.jp/wiki/Item:Q297 | K8: =VLOOKUP(B8,dict.term!A:G,7,FALSE)&"" -> 2022-07-11 04:36:42.734137+00 | L8: =D8&"/"&F8 -> 有機材料/融点 | M8: =E8&"/"&G8 -> organic material/Melting temperature
A9: 932e4fe1-9724-305f-ffc5-1908c31c83e5 | B9: 70c2c751-5404-19b7-4a5e-981e6cebbb15 | C9: sample.specific.inorganic.name | D9: =VLOOKUP(A9,sample.sample_class!A:C,2,FALSE)&"" -> 無機材料 | E9: =VLOOKUP(A9,sample.sample_class!A:C,3,FALSE)&"" -> inorganic material | F9: =VLOOKUP(B9,dict.term!A:G,2,FALSE)&"" -> 名称 | G9: =VLOOKUP(B9,dict.term!A:G,3,FALSE)&"" -> Name | H9: =VLOOKUP(B9,dict.term!A:G,4,FALSE)&"" -> 名称を入力してください | I9: =VLOOKUP(B9,dict.term!A:G,5,FALSE)&"" -> Please enter Name | J9: =VLOOKUP(B9,dict.term!A:G,6,FALSE)&"" -> NULL | K9: =VLOOKUP(B9,dict.term!A:G,7,FALSE)&"" -> 2022-07-11 04:36:42.734137+00 | L9: =D9&"/"&F9 -> 無機材料/名称 | M9: =E9&"/"&G9 -> inorganic material/Name
A10: 932e4fe1-9724-305f-ffc5-1908c31c83e5 | B10: 3250c45d-0ed6-1438-43b5-eb679918604a | C10: sample.specific.inorganic.chemical-formula | D10: =VLOOKUP(A10,sample.sample_class!A:C,2,FALSE)&"" -> 無機材料 | E10: =VLOOKUP(A10,sample.sample_class!A:C,3,FALSE)&"" -> inorganic material | F10: =VLOOKUP(B10,dict.term!A:G,2,FALSE)&"" -> 化学式 | G10: =VLOOKUP(B10,dict.term!A:G,3,FALSE)&"" -> Chemical formula | H10: =VLOOKUP(B10,dict.term!A:G,4,FALSE)&"" -> 化学式を入力してください | I10: =VLOOKUP(B10,dict.term!A:G,5,FALSE)&"" -> Please enter Chemical formula | J10: =VLOOKUP(B10,dict.term!A:G,6,FALSE)&"" -> NULL | K10: =VLOOKUP(B10,dict.term!A:G,7,FALSE)&"" -> 2022-07-11 04:36:42.734137+00 | L10: =D10&"/"&F10 -> 無機材料/化学式 | M10: =E10&"/"&G10 -> inorganic material/Chemical formula
A11: 932e4fe1-9724-305f-ffc5-1908c31c83e5 | B11: f63149a4-e57c-4273-4c1e-dffa41356d28 | C11: sample.specific.inorganic.space-group | D11: =VLOOKUP(A11,sample.sample_class!A:C,2,FALSE)&"" -> 無機材料 | E11: =VLOOKUP(A11,sample.sample_class!A:C,3,FALSE)&"" -> inorganic material | F11: =VLOOKUP(B11,dict.term!A:G,2,FALSE)&"" -> 空間群 | G11: =VLOOKUP(B11,dict.term!A:G,3,FALSE)&"" -> Space group | H11: =VLOOKUP(B11,dict.term!A:G,4,FALSE)&"" -> 空間群を入力してください | I11: =VLOOKUP(B11,dict.term!A:G,5,FALSE)&"" -> Please enter Space group | J11: =VLOOKUP(B11,dict.term!A:G,6,FALSE)&"" -> https://matvoc.nims.go.jp/wiki/Item:Q224 | K11: =VLOOKUP(B11,dict.term!A:G,7,FALSE)&"" -> 2022-07-11 04:36:42.734137+00 | L11: =D11&"/"&F11 -> 無機材料/空間群 | M11: =E11&"/"&G11 -> inorganic material/Space group
A12: a674a8ef-efa8-9497-4ed4-74de55fafddb | B12: 3250c45d-0ed6-1438-43b5-eb679918604a | C12: sample.specific.metals.chemical-formula | D12: =VLOOKUP(A12,sample.sample_class!A:C,2,FALSE)&"" -> 金属・合金 | E12: =VLOOKUP(A12,sample.sample_class!A:C,3,FALSE)&"" -> metals and alloys | F12: =VLOOKUP(B12,dict.term!A:G,2,FALSE)&"" -> 化学式 | G12: =VLOOKUP(B12,dict.term!A:G,3,FALSE)&"" -> Chemical formula | H12: =VLOOKUP(B12,dict.term!A:G,4,FALSE)&"" -> 化学式を入力してください | I12: =VLOOKUP(B12,dict.term!A:G,5,FALSE)&"" -> Please enter Chemical formula | J12: =VLOOKUP(B12,dict.term!A:G,6,FALSE)&"" -> NULL | K12: =VLOOKUP(B12,dict.term!A:G,7,FALSE)&"" -> 2022-07-11 04:36:42.734137+00 | L12: =D12&"/"&F12 -> 金属・合金/化学式 | M12: =E12&"/"&G12 -> metals and alloys/Chemical formula
A13: a674a8ef-efa8-9497-4ed4-74de55fafddb | B13: 70c2c751-5404-19b7-4a5e-981e6cebbb15 | C13: sample.specific.metals.name | D13: =VLOOKUP(A13,sample.sample_class!A:C,2,FALSE)&"" -> 金属・合金 | E13: =VLOOKUP(A13,sample.sample_class!A:C,3,FALSE)&"" -> metals and alloys | F13: =VLOOKUP(B13,dict.term!A:G,2,FALSE)&"" -> 名称 | G13: =VLOOKUP(B13,dict.term!A:G,3,FALSE)&"" -> Name | H13: =VLOOKUP(B13,dict.term!A:G,4,FALSE)&"" -> 名称を入力してください | I13: =VLOOKUP(B13,dict.term!A:G,5,FALSE)&"" -> Please enter Name | J13: =VLOOKUP(B13,dict.term!A:G,6,FALSE)&"" -> NULL | K13: =VLOOKUP(B13,dict.term!A:G,7,FALSE)&"" -> 2022-07-11 04:36:42.734137+00 | L13: =D13&"/"&F13 -> 金属・合金/名称 | M13: =E13&"/"&G13 -> metals and alloys/Name
... A36: 01cb3c01-37a4-5a43-d8ca-f523ca99a75b | B36: 3edadcff-8a85-51d9-708f-8f76bf055377 | C36: sample.specific.organic-material.inchi-key | D36: =VLOOKUP(A36,sample.sample_class!A:C,2,FALSE)&"" -> 有機材料 | E36: =VLOOKUP(A36,sample.sample_class!A:C,3,FALSE)&"" -> organic material | F36: =VLOOKUP(B36,dict.term!A:G,2,FALSE)&"" -> InChI key | G36: =VLOOKUP(B36,dict.term!A:G,3,FALSE)&"" -> InChI key | H36: =VLOOKUP(B36,dict.term!A:G,4,FALSE)&"" -> InChI keyを入力してください | I36: =VLOOKUP(B36,dict.term!A:G,5,FALSE)&"" -> Please enter InChI key | J36: =VLOOKUP(B36,dict.term!A:G,6,FALSE)&"" -> NULL | K36: =VLOOKUP(B36,dict.term!A:G,7,FALSE)&"" -> 2022-08-01 09:32:47.462801+00 | L36: =D36&"/"&F36 -> 有機材料/InChI key | M36: =E36&"/"&G36 -> organic material/InChI key
